<?xml version="1.0"?>
<!-- URDF WORKS TILL wrist. Need to fix positioning and then work on gripper -->
<robot name="testing-robot">

  <link name="world"></link>

  <joint name="base_joint" type="fixed">
      <origin xyz="1 1.5 0" rpy="0 0 0"/>
      <parent link="world"/>
      <child link="base_link"/>
      
  </joint>

  <!-- Base Link -->
  <link name="base_link">
    <visual>
      <origin xyz="0 0 0" rpy="0 0 0"/>
      <geometry>
        <mesh filename="package://my_robot_rviz/meshes/Base.dae" scale="1 1 1"/>
      </geometry>
      <!-- <geometry>
        <box size="0.2 0.2 0.2"/>
      </geometry> -->

    </visual>
    <collision>
      <origin xyz="0 0 0" rpy="0 0 0"/>
      <geometry>
        <mesh filename="package://my_robot_rviz/meshes/Base.dae" scale="1 1 1"/>
      </geometry>
      <!-- <geometry>
        <box size="0.2 0.2 0.2"/>
      </geometry> -->

    </collision>
  </link>

  <!-- Revolute joint connecting base_link to central_axis_link -->
  <joint name="joint_base_to_central" type="revolute">
    <origin xyz="0 0 0.046553787"/>
    <parent link="base_link"/>
    <child link="central_axis_link"/>
    <axis xyz="0 0 1"/>
    <limit lower="0" upper="3.14" effort="100" velocity="100"/>
    
    
    
    
  </joint>

  <!-- Central Axis Link -->
  <link name="central_axis_link">
    <visual>
      <origin xyz="0 0 -0.046553787" rpy="0 0 0"/>
      <geometry>
        <mesh filename="package://my_robot_rviz/meshes/EjeCentral.dae" scale="1 1 1"/>
      </geometry>
      <!-- <geometry>
        <box size="0.2 0.2 0.2"/>
      </geometry> -->

    </visual>
    <collision>
      <origin xyz="0 0 -0.046553787" rpy="0 0 0"/>
      <geometry>
        <mesh filename="package://my_robot_rviz/meshes/EjeCentral.dae" scale="1 1 1"/>
      </geometry>
      <!-- <geometry>
        <box size="0.2 0.2 0.2"/>
      </geometry> -->

    </collision>
  </link>

  <!-- Revolute joint: central_axis_link to arm_link -->
  <joint name="joint_central_to_forearm" type="revolute">
    <parent link="central_axis_link"/>
    <child link="forearm_link"/>
    <origin xyz="-0.0075 0 0.06" rpy="0 0 0"/>
    <axis xyz="0 1 0"/>
    <limit lower="-1.57" upper="1.57" effort="10" velocity="1"/>
  </joint>

  <!-- Forearm Link -->
  <link name="forearm_link">
    <visual>
      <origin xyz="0.0075 0 -0.106553787" rpy="0 0 0"/>
      <geometry>
        <mesh filename="package://my_robot_rviz/meshes/Antebrazo.dae" scale="1 1 1"/>
      </geometry>
    </visual>
    <collision>
      <origin xyz="0.0075 0 -0.106553787" rpy="0 0 0"/>
      <geometry>
        <mesh filename="package://my_robot_rviz/meshes/Antebrazo.dae" scale="1 1 1"/>
      </geometry>
    </collision> 
  </link>

  <!-- Revolute joint: arm_link to forearm_link -->
  <joint name="joint_forearm_to_arm" type="revolute">
    <parent link="forearm_link"/>
    <child link="arm_link"/>
    <origin xyz="0 0 0.12" rpy="0 0 0"/>
    <axis xyz="0 1 0"/>
    <limit lower="-1.57" upper="1.57" effort="10" velocity="1"/>
  </joint>

  <!-- Arm Link -->
  <link name="arm_link">
    <visual>
      <origin xyz="0.0075 0 -0.226553787" rpy="0 0 0"/>
      <geometry>
        <mesh filename="package://my_robot_rviz/meshes/Brazo.dae" scale="1 1 1"/>
      </geometry>
    </visual>
    <collision>
      <origin xyz="0.0075 0 -0.226553787" rpy="0 0 0"/>
      <geometry>
        <mesh filename="package://my_robot_rviz/meshes/Brazo.dae" scale="1 1 1"/>
      </geometry>
    </collision>
  </link>

  <!-- Revolute joint: forearm_link to wrist_link -->
  <joint name="joint_arm_to_wrist" type="revolute">
    <parent link="arm_link"/>
    <child link="wrist_link"/>
    <origin xyz="-0.06 -0.011158664703 0.02" rpy="0 0 0"/>
    <axis xyz="1 0 0"/>
    <limit lower="-1.57" upper="1.57" effort="10" velocity="1"/>
  </joint>

  <!-- Wrist Link -->
  <link name="wrist_link">
    <visual>
      <origin xyz="0.0675 0.011158664703 -0.24755378" rpy="0 0 0"/>
      <geometry>
        <mesh filename="package://my_robot_rviz/meshes/Muteca.dae" scale="1 1 1"/>
      </geometry>
    </visual>
    <collision>
      <origin xyz="0.0675 0.011158664703 -0.24755378" rpy="0 0 0"/>
      <geometry>
        <mesh filename="package://my_robot_rviz/meshes/Muteca.dae" scale="1 1 1"/>
      </geometry>
    </collision>
  </link>

  <!-- Revolute joint: wrist_link to gripper_base_link -->
  <joint name="joint_wrist_to_gripper_base" type="revolute">
    <parent link="wrist_link"/>
    <child link="gripper_base_link"/>
    <origin xyz="-0.06 0 0" rpy="0 0 0"/>
    <axis xyz="0 1 0"/>
    <limit lower="-1.57" upper="1.57" effort="10" velocity="1"/>
  </joint>

  <!-- Gripper Base Link -->
  <link name="gripper_base_link">
    <visual>
      <origin xyz="0.1275 0.011158664703 -0.24755378" rpy="0 0 0"/>
      <geometry>
        <mesh filename="package://my_robot_rviz/meshes/Basedelagarra.dae" scale="1 1 1"/>
      </geometry>
    </visual>
    <collision>
      <origin xyz="0 0 0" rpy="0 0 0"/>
      <geometry>
        <mesh filename="package://my_robot_rviz/meshes/Basedelagarra.dae" scale="1 1 1"/>
      </geometry>
    </collision>
  </link>

  <joint name="joint_base_tapapgarra" type="fixed">
    <parent link="gripper_base_link"/>
    <child link="tapapgarra_link"/>
    <origin xyz="-0.05 0 0" rpy="0 0 0"/>
  </joint>

  <link name = "tapapgarra_link">
    <visual>
      <origin xyz="0.1775 0.011158664703 -0.24755378" rpy="0 0 0"/>
      <geometry>
        <mesh filename="package://my_robot_rviz/meshes/Tapapgarra.dae" scale="1 1 1"/>
      </geometry>
    </visual>
    <collision>
      <origin xyz="0.1775 0.011158664703 -0.24755378" rpy="0 0 0"/>
      <geometry>
        <mesh filename="package://my_robot_rviz/meshes/Tapapgarra.dae" scale="1 1 1"/>
      </geometry>
    </collision>
  </link>

  <joint name="joint_base_engranaje1" type="revolute">
    <parent link="gripper_base_link"/>
    <child link="engranaje1_link"/>
    <origin xyz="-0.035 0.01 0" rpy="0 0 0"/>
    <axis xyz="0 0 1"/>
    <limit lower="-1.57" upper="0" effort="5" velocity="1"/>
  </joint>

  <link name = "engranaje1_link">
    <visual>
      <origin xyz="0.1625 0.001158665 -0.24755378" rpy="0 0 0"/>
      <geometry>
        <mesh filename="package://my_robot_rviz/meshes/Engranaje1.dae" scale="1 1 1"/>
      </geometry>
    </visual>
    <collision>
      <origin xyz="0.1625 0.001158665 -0.24755378" rpy="0 0 0"/>
      <geometry>
        <mesh filename="package://my_robot_rviz/meshes/Engranaje1.dae" scale="1 1 1"/>
      </geometry>
    </collision>
  </link>

  <joint name="joint_base_barra1" type="fixed">
    <parent link="engranaje1_link"/>
    <child link="barra1_link"/>
    <origin xyz="0 0 0" rpy="0 0 0"/>
  </joint>

    <link name = "barra1_link">
    <visual>
      <origin xyz="0 0 0" rpy="0 0 0"/>
      <geometry>
        <mesh filename="package://my_robot_rviz/meshes/Barra1.dae" scale="1 1 1"/>
      </geometry>
    </visual>
    <collision>
      <origin xyz="0 0 0" rpy="0 0 0"/>
      <geometry>
        <mesh filename="package://my_robot_rviz/meshes/Barra1.dae" scale="1 1 1"/>
      </geometry>
    </collision>
  </link>


  <joint name="joint_base_engranaje2" type="revolute">
    <parent link="gripper_base_link"/>
    <child link="engranaje2_link"/>
    <origin xyz="-0.035 -0.01 0" rpy="0 0 0"/>
    <axis xyz="0 0 1"/>
    <limit lower="0" upper="3.14" effort="5" velocity="1"/>
  </joint>

  <link name = "engranaje2_link">
    <visual>
      <origin xyz="0.1625 0.02 -0.24755378" rpy="0 0 0"/>
      <geometry>
        <mesh filename="package://my_robot_rviz/meshes/Engranaje2.dae" scale="1 1 1"/>
      </geometry>
    </visual>
    <collision>
      <origin xyz="0.1625 0.02 -0.24755378" rpy="0 0 0"/>
      <geometry>
        <mesh filename="package://my_robot_rviz/meshes/Engranaje2.dae" scale="1 1 1"/>
      </geometry>
    </collision>
  </link>


  <joint name="joint_base_barra2" type="revolute">
    <parent link="gripper_base_link"/>
    <child link="barra2_link"/>
    <origin xyz="0 0 0" rpy="0 0 0"/>
    <axis xyz="0 0 1"/>
    <limit lower="0" upper="3.14" effort="5" velocity="1"/>
  </joint>

  <link name = "barra2_link">
    <visual>
      <origin xyz="0 0 0" rpy="0 0 0"/>
      <geometry>
        <mesh filename="package://my_robot_rviz/meshes/Barra2.dae" scale="1 1 1"/>
      </geometry>
    </visual>
    <collision>
      <origin xyz="0 0 0" rpy="0 0 0"/>
      <geometry>
        <mesh filename="package://my_robot_rviz/meshes/Barra2.dae" scale="1 1 1"/>
      </geometry>
    </collision>
  </link>

  <!-- Revolute joint: gripper_base_link to gripper_finger1_link -->
  <joint name="joint_engranaje1_finger1" type="fixed">
    <parent link="engranaje1_link"/>
    <child link="gripper_finger1_link"/>
    <origin xyz="0 0 0" rpy="0 0 0"/>
  </joint>

  <joint name="joint_barra1_finger1" type="fixed">
    <parent link="barra1_link"/>
    <child link="gripper_finger1_link"/>
    <origin xyz="0 0 0" rpy="0 0 0"/>
  </joint>

  <!-- Gripper finger 1 -->
  <link name="gripper_finger1_link">
    <visual>
      <origin xyz="0 0 0" rpy="0 0 0"/>
      <geometry>
        <mesh filename="package://my_robot_rviz/meshes/Pinza1.dae" scale="1 1 1"/>
      </geometry>
    </visual>
    <collision>
      <origin xyz="0 0 0" rpy="0 0 0"/>
      <geometry>
        <mesh filename="package://my_robot_rviz/meshes/Pinza1.dae" scale="1 1 1"/>
      </geometry>
    </collision>
  </link>

  <!-- Revolute joint: gripper_base_link to gripper_finger2_link -->
  <joint name="joint_engranaje2_finger2" type="fixed">
    <parent link="engranaje2_link"/>
    <child link="gripper_finger2_link"/>
    <!-- <origin xyz="0 0 0" rpy="0 0 0"/>
    <axis xyz="0 1 0"/>
    <limit lower="0" upper="3.14" effort="5" velocity="1"/> -->
  </joint>

  <!-- Revolute joint: gripper_base_link to gripper_finger2_link -->
  <joint name="joint_barra2_finger2" type="fixed">
    <parent link="barra2_link"/>
    <child link="gripper_finger2_link"/>
    <!-- <origin xyz="0 0 0" rpy="0 0 0"/>
    <axis xyz="0 1 0"/>
    <limit lower="0" upper="3.14" effort="5" velocity="1"/> -->
  </joint>

  <!-- Gripper finger 2 -->
  <link name="gripper_finger2_link">
    <visual>
      <origin xyz="0 0 0" rpy="0 0 0"/>
      <geometry>
        <mesh filename="package://my_robot_rviz/meshes/Pinza2.dae" scale="1 1 1"/>
      </geometry>
    </visual>
    <collision>
      <origin xyz="0 0 0" rpy="0 0 0"/>
      <geometry>
        <mesh filename="package://my_robot_rviz/meshes/Pinza2.dae" scale="1 1 1"/>
      </geometry>
    </collision>
  </link>

</robot>
